import {
  throwError,
  throwCustomError,
  resolveValue,
  MyAwesomeError,
  rejectCustomError,
} from './index';

describe('resolveValue', () => {
  test('should resolve provided value', async () => {
    const value = 'test';
    const resolvedValue = await resolveValue(value);
    expect(resolvedValue).toBe(value);
  });
});

describe('throwError', () => {
  test('should throw error with provided message', () => {
    const errorMesage = 'Something went wrong';
    expect(() => throwError(errorMesage)).toThrowError(errorMesage);
  });

  test('should throw error with default message if message is not provided', () => {
    expect(() => throwError()).toThrowError('Oops!');
  });
});

describe('throwCustomError', () => {
  test('should throw custom error', () => {
    expect(() => throwCustomError()).toThrow(MyAwesomeError);
  });
});

describe('rejectCustomError', () => {
  test('should reject custom error', async () => {
    try {
      await rejectCustomError();
    } catch (error) {
      expect(error).toBeInstanceOf(MyAwesomeError);
    }
  });
});
